{
 "cells": [
  {
   "cell_type": "code",
   "execution_count": 13,
   "metadata": {},
   "outputs": [],
   "source": [
    "import numpy as np\n",
    "from keras.datasets import imdb\n",
    "from keras.preprocessing.sequence import pad_sequences\n",
    "from keras.models import Sequential\n",
    "from keras.layers import Embedding, SimpleRNN, Dense\n",
    "from keras.optimizers import Adam\n",
    "from keras.callbacks import ReduceLROnPlateau\n",
    "\n",
    "from sklearn.model_selection import GridSearchCV\n",
    "from scikeras.wrappers import KerasClassifier, KerasRegressor"
   ]
  },
  {
   "cell_type": "code",
   "execution_count": 4,
   "metadata": {},
   "outputs": [
    {
     "name": "stdout",
     "output_type": "stream",
     "text": [
      "Downloading data from https://storage.googleapis.com/tensorflow/tf-keras-datasets/imdb.npz\n",
      "\u001b[1m17464789/17464789\u001b[0m \u001b[32m━━━━━━━━━━━━━━━━━━━━\u001b[0m\u001b[37m\u001b[0m \u001b[1m3s\u001b[0m 0us/step\n"
     ]
    }
   ],
   "source": [
    "# Load data\n",
    "max_features = 10000\n",
    "max_len = 500\n",
    "(X_train, y_train), (X_test, y_test) = imdb.load_data(num_words=max_features)\n",
    "\n",
    "# Preprocess data\n",
    "X_train = pad_sequences(X_train, maxlen=max_len)\n",
    "X_test = pad_sequences(X_test, maxlen=max_len)"
   ]
  },
  {
   "cell_type": "code",
   "execution_count": 5,
   "metadata": {},
   "outputs": [],
   "source": [
    "def create_model(optimizer='adam'):\n",
    "    model = Sequential()\n",
    "    model.add(Embedding(max_features, 32))\n",
    "    model.add(SimpleRNN(32))\n",
    "    model.add(Dense(1, activation='sigmoid'))\n",
    "    model.compile(loss='binary_crossentropy', optimizer=optimizer, metrics=['accuracy'])\n",
    "    return model"
   ]
  },
  {
   "cell_type": "code",
   "execution_count": null,
   "metadata": {},
   "outputs": [],
   "source": []
  },
  {
   "cell_type": "code",
   "execution_count": 18,
   "metadata": {},
   "outputs": [
    {
     "ename": "ValueError",
     "evalue": "\nAll the 40 fits failed.\nIt is very likely that your model is misconfigured.\nYou can try to debug the error by setting error_score='raise'.\n\nBelow are more details about the failures:\n--------------------------------------------------------------------------------\n2 fits failed with the following error:\nTraceback (most recent call last):\n  File \"c:\\Users\\korem\\AppData\\Local\\Programs\\Python\\Python312\\Lib\\site-packages\\sklearn\\model_selection\\_validation.py\", line 895, in _fit_and_score\n    estimator.fit(X_train, y_train, **fit_params)\n  File \"c:\\Users\\korem\\AppData\\Local\\Programs\\Python\\Python312\\Lib\\site-packages\\scikeras\\wrappers.py\", line 1501, in fit\n    super().fit(X=X, y=y, sample_weight=sample_weight, **kwargs)\n  File \"c:\\Users\\korem\\AppData\\Local\\Programs\\Python\\Python312\\Lib\\site-packages\\scikeras\\wrappers.py\", line 770, in fit\n    self._fit(\n  File \"c:\\Users\\korem\\AppData\\Local\\Programs\\Python\\Python312\\Lib\\site-packages\\scikeras\\wrappers.py\", line 936, in _fit\n    self._check_model_compatibility(y)\n  File \"c:\\Users\\korem\\AppData\\Local\\Programs\\Python\\Python312\\Lib\\site-packages\\scikeras\\wrappers.py\", line 559, in _check_model_compatibility\n    if self.n_outputs_expected_ != len(self.model_.outputs):\n                                       ^^^^^^^^^^^^^^^^^^^\n  File \"c:\\Users\\korem\\AppData\\Local\\Programs\\Python\\Python312\\Lib\\site-packages\\keras\\src\\models\\sequential.py\", line 280, in outputs\n    raise ValueError(\nValueError: Sequential model 'sequential_4' has no defined outputs yet.\n\n--------------------------------------------------------------------------------\n5 fits failed with the following error:\nTraceback (most recent call last):\n  File \"c:\\Users\\korem\\AppData\\Local\\Programs\\Python\\Python312\\Lib\\site-packages\\sklearn\\model_selection\\_validation.py\", line 895, in _fit_and_score\n    estimator.fit(X_train, y_train, **fit_params)\n  File \"c:\\Users\\korem\\AppData\\Local\\Programs\\Python\\Python312\\Lib\\site-packages\\scikeras\\wrappers.py\", line 1501, in fit\n    super().fit(X=X, y=y, sample_weight=sample_weight, **kwargs)\n  File \"c:\\Users\\korem\\AppData\\Local\\Programs\\Python\\Python312\\Lib\\site-packages\\scikeras\\wrappers.py\", line 770, in fit\n    self._fit(\n  File \"c:\\Users\\korem\\AppData\\Local\\Programs\\Python\\Python312\\Lib\\site-packages\\scikeras\\wrappers.py\", line 936, in _fit\n    self._check_model_compatibility(y)\n  File \"c:\\Users\\korem\\AppData\\Local\\Programs\\Python\\Python312\\Lib\\site-packages\\scikeras\\wrappers.py\", line 559, in _check_model_compatibility\n    if self.n_outputs_expected_ != len(self.model_.outputs):\n                                       ^^^^^^^^^^^^^^^^^^^\n  File \"c:\\Users\\korem\\AppData\\Local\\Programs\\Python\\Python312\\Lib\\site-packages\\keras\\src\\models\\sequential.py\", line 280, in outputs\n    raise ValueError(\nValueError: Sequential model 'sequential_5' has no defined outputs yet.\n\n--------------------------------------------------------------------------------\n7 fits failed with the following error:\nTraceback (most recent call last):\n  File \"c:\\Users\\korem\\AppData\\Local\\Programs\\Python\\Python312\\Lib\\site-packages\\sklearn\\model_selection\\_validation.py\", line 895, in _fit_and_score\n    estimator.fit(X_train, y_train, **fit_params)\n  File \"c:\\Users\\korem\\AppData\\Local\\Programs\\Python\\Python312\\Lib\\site-packages\\scikeras\\wrappers.py\", line 1501, in fit\n    super().fit(X=X, y=y, sample_weight=sample_weight, **kwargs)\n  File \"c:\\Users\\korem\\AppData\\Local\\Programs\\Python\\Python312\\Lib\\site-packages\\scikeras\\wrappers.py\", line 770, in fit\n    self._fit(\n  File \"c:\\Users\\korem\\AppData\\Local\\Programs\\Python\\Python312\\Lib\\site-packages\\scikeras\\wrappers.py\", line 936, in _fit\n    self._check_model_compatibility(y)\n  File \"c:\\Users\\korem\\AppData\\Local\\Programs\\Python\\Python312\\Lib\\site-packages\\scikeras\\wrappers.py\", line 559, in _check_model_compatibility\n    if self.n_outputs_expected_ != len(self.model_.outputs):\n                                       ^^^^^^^^^^^^^^^^^^^\n  File \"c:\\Users\\korem\\AppData\\Local\\Programs\\Python\\Python312\\Lib\\site-packages\\keras\\src\\models\\sequential.py\", line 280, in outputs\n    raise ValueError(\nValueError: Sequential model 'sequential_6' has no defined outputs yet.\n\n--------------------------------------------------------------------------------\n1 fits failed with the following error:\nTraceback (most recent call last):\n  File \"c:\\Users\\korem\\AppData\\Local\\Programs\\Python\\Python312\\Lib\\site-packages\\sklearn\\model_selection\\_validation.py\", line 895, in _fit_and_score\n    estimator.fit(X_train, y_train, **fit_params)\n  File \"c:\\Users\\korem\\AppData\\Local\\Programs\\Python\\Python312\\Lib\\site-packages\\scikeras\\wrappers.py\", line 1501, in fit\n    super().fit(X=X, y=y, sample_weight=sample_weight, **kwargs)\n  File \"c:\\Users\\korem\\AppData\\Local\\Programs\\Python\\Python312\\Lib\\site-packages\\scikeras\\wrappers.py\", line 770, in fit\n    self._fit(\n  File \"c:\\Users\\korem\\AppData\\Local\\Programs\\Python\\Python312\\Lib\\site-packages\\scikeras\\wrappers.py\", line 936, in _fit\n    self._check_model_compatibility(y)\n  File \"c:\\Users\\korem\\AppData\\Local\\Programs\\Python\\Python312\\Lib\\site-packages\\scikeras\\wrappers.py\", line 559, in _check_model_compatibility\n    if self.n_outputs_expected_ != len(self.model_.outputs):\n                                       ^^^^^^^^^^^^^^^^^^^\n  File \"c:\\Users\\korem\\AppData\\Local\\Programs\\Python\\Python312\\Lib\\site-packages\\keras\\src\\models\\sequential.py\", line 280, in outputs\n    raise ValueError(\nValueError: Sequential model 'sequential_3' has no defined outputs yet.\n\n--------------------------------------------------------------------------------\n6 fits failed with the following error:\nTraceback (most recent call last):\n  File \"c:\\Users\\korem\\AppData\\Local\\Programs\\Python\\Python312\\Lib\\site-packages\\sklearn\\model_selection\\_validation.py\", line 895, in _fit_and_score\n    estimator.fit(X_train, y_train, **fit_params)\n  File \"c:\\Users\\korem\\AppData\\Local\\Programs\\Python\\Python312\\Lib\\site-packages\\scikeras\\wrappers.py\", line 1501, in fit\n    super().fit(X=X, y=y, sample_weight=sample_weight, **kwargs)\n  File \"c:\\Users\\korem\\AppData\\Local\\Programs\\Python\\Python312\\Lib\\site-packages\\scikeras\\wrappers.py\", line 770, in fit\n    self._fit(\n  File \"c:\\Users\\korem\\AppData\\Local\\Programs\\Python\\Python312\\Lib\\site-packages\\scikeras\\wrappers.py\", line 936, in _fit\n    self._check_model_compatibility(y)\n  File \"c:\\Users\\korem\\AppData\\Local\\Programs\\Python\\Python312\\Lib\\site-packages\\scikeras\\wrappers.py\", line 559, in _check_model_compatibility\n    if self.n_outputs_expected_ != len(self.model_.outputs):\n                                       ^^^^^^^^^^^^^^^^^^^\n  File \"c:\\Users\\korem\\AppData\\Local\\Programs\\Python\\Python312\\Lib\\site-packages\\keras\\src\\models\\sequential.py\", line 280, in outputs\n    raise ValueError(\nValueError: Sequential model 'sequential_7' has no defined outputs yet.\n\n--------------------------------------------------------------------------------\n6 fits failed with the following error:\nTraceback (most recent call last):\n  File \"c:\\Users\\korem\\AppData\\Local\\Programs\\Python\\Python312\\Lib\\site-packages\\sklearn\\model_selection\\_validation.py\", line 895, in _fit_and_score\n    estimator.fit(X_train, y_train, **fit_params)\n  File \"c:\\Users\\korem\\AppData\\Local\\Programs\\Python\\Python312\\Lib\\site-packages\\scikeras\\wrappers.py\", line 1501, in fit\n    super().fit(X=X, y=y, sample_weight=sample_weight, **kwargs)\n  File \"c:\\Users\\korem\\AppData\\Local\\Programs\\Python\\Python312\\Lib\\site-packages\\scikeras\\wrappers.py\", line 770, in fit\n    self._fit(\n  File \"c:\\Users\\korem\\AppData\\Local\\Programs\\Python\\Python312\\Lib\\site-packages\\scikeras\\wrappers.py\", line 936, in _fit\n    self._check_model_compatibility(y)\n  File \"c:\\Users\\korem\\AppData\\Local\\Programs\\Python\\Python312\\Lib\\site-packages\\scikeras\\wrappers.py\", line 559, in _check_model_compatibility\n    if self.n_outputs_expected_ != len(self.model_.outputs):\n                                       ^^^^^^^^^^^^^^^^^^^\n  File \"c:\\Users\\korem\\AppData\\Local\\Programs\\Python\\Python312\\Lib\\site-packages\\keras\\src\\models\\sequential.py\", line 280, in outputs\n    raise ValueError(\nValueError: Sequential model 'sequential_8' has no defined outputs yet.\n\n--------------------------------------------------------------------------------\n5 fits failed with the following error:\nTraceback (most recent call last):\n  File \"c:\\Users\\korem\\AppData\\Local\\Programs\\Python\\Python312\\Lib\\site-packages\\sklearn\\model_selection\\_validation.py\", line 895, in _fit_and_score\n    estimator.fit(X_train, y_train, **fit_params)\n  File \"c:\\Users\\korem\\AppData\\Local\\Programs\\Python\\Python312\\Lib\\site-packages\\scikeras\\wrappers.py\", line 1501, in fit\n    super().fit(X=X, y=y, sample_weight=sample_weight, **kwargs)\n  File \"c:\\Users\\korem\\AppData\\Local\\Programs\\Python\\Python312\\Lib\\site-packages\\scikeras\\wrappers.py\", line 770, in fit\n    self._fit(\n  File \"c:\\Users\\korem\\AppData\\Local\\Programs\\Python\\Python312\\Lib\\site-packages\\scikeras\\wrappers.py\", line 936, in _fit\n    self._check_model_compatibility(y)\n  File \"c:\\Users\\korem\\AppData\\Local\\Programs\\Python\\Python312\\Lib\\site-packages\\scikeras\\wrappers.py\", line 559, in _check_model_compatibility\n    if self.n_outputs_expected_ != len(self.model_.outputs):\n                                       ^^^^^^^^^^^^^^^^^^^\n  File \"c:\\Users\\korem\\AppData\\Local\\Programs\\Python\\Python312\\Lib\\site-packages\\keras\\src\\models\\sequential.py\", line 280, in outputs\n    raise ValueError(\nValueError: Sequential model 'sequential_9' has no defined outputs yet.\n\n--------------------------------------------------------------------------------\n4 fits failed with the following error:\nTraceback (most recent call last):\n  File \"c:\\Users\\korem\\AppData\\Local\\Programs\\Python\\Python312\\Lib\\site-packages\\sklearn\\model_selection\\_validation.py\", line 895, in _fit_and_score\n    estimator.fit(X_train, y_train, **fit_params)\n  File \"c:\\Users\\korem\\AppData\\Local\\Programs\\Python\\Python312\\Lib\\site-packages\\scikeras\\wrappers.py\", line 1501, in fit\n    super().fit(X=X, y=y, sample_weight=sample_weight, **kwargs)\n  File \"c:\\Users\\korem\\AppData\\Local\\Programs\\Python\\Python312\\Lib\\site-packages\\scikeras\\wrappers.py\", line 770, in fit\n    self._fit(\n  File \"c:\\Users\\korem\\AppData\\Local\\Programs\\Python\\Python312\\Lib\\site-packages\\scikeras\\wrappers.py\", line 936, in _fit\n    self._check_model_compatibility(y)\n  File \"c:\\Users\\korem\\AppData\\Local\\Programs\\Python\\Python312\\Lib\\site-packages\\scikeras\\wrappers.py\", line 559, in _check_model_compatibility\n    if self.n_outputs_expected_ != len(self.model_.outputs):\n                                       ^^^^^^^^^^^^^^^^^^^\n  File \"c:\\Users\\korem\\AppData\\Local\\Programs\\Python\\Python312\\Lib\\site-packages\\keras\\src\\models\\sequential.py\", line 280, in outputs\n    raise ValueError(\nValueError: Sequential model 'sequential_10' has no defined outputs yet.\n\n--------------------------------------------------------------------------------\n3 fits failed with the following error:\nTraceback (most recent call last):\n  File \"c:\\Users\\korem\\AppData\\Local\\Programs\\Python\\Python312\\Lib\\site-packages\\sklearn\\model_selection\\_validation.py\", line 895, in _fit_and_score\n    estimator.fit(X_train, y_train, **fit_params)\n  File \"c:\\Users\\korem\\AppData\\Local\\Programs\\Python\\Python312\\Lib\\site-packages\\scikeras\\wrappers.py\", line 1501, in fit\n    super().fit(X=X, y=y, sample_weight=sample_weight, **kwargs)\n  File \"c:\\Users\\korem\\AppData\\Local\\Programs\\Python\\Python312\\Lib\\site-packages\\scikeras\\wrappers.py\", line 770, in fit\n    self._fit(\n  File \"c:\\Users\\korem\\AppData\\Local\\Programs\\Python\\Python312\\Lib\\site-packages\\scikeras\\wrappers.py\", line 936, in _fit\n    self._check_model_compatibility(y)\n  File \"c:\\Users\\korem\\AppData\\Local\\Programs\\Python\\Python312\\Lib\\site-packages\\scikeras\\wrappers.py\", line 559, in _check_model_compatibility\n    if self.n_outputs_expected_ != len(self.model_.outputs):\n                                       ^^^^^^^^^^^^^^^^^^^\n  File \"c:\\Users\\korem\\AppData\\Local\\Programs\\Python\\Python312\\Lib\\site-packages\\keras\\src\\models\\sequential.py\", line 280, in outputs\n    raise ValueError(\nValueError: Sequential model 'sequential_11' has no defined outputs yet.\n\n--------------------------------------------------------------------------------\n1 fits failed with the following error:\nTraceback (most recent call last):\n  File \"c:\\Users\\korem\\AppData\\Local\\Programs\\Python\\Python312\\Lib\\site-packages\\sklearn\\model_selection\\_validation.py\", line 895, in _fit_and_score\n    estimator.fit(X_train, y_train, **fit_params)\n  File \"c:\\Users\\korem\\AppData\\Local\\Programs\\Python\\Python312\\Lib\\site-packages\\scikeras\\wrappers.py\", line 1501, in fit\n    super().fit(X=X, y=y, sample_weight=sample_weight, **kwargs)\n  File \"c:\\Users\\korem\\AppData\\Local\\Programs\\Python\\Python312\\Lib\\site-packages\\scikeras\\wrappers.py\", line 770, in fit\n    self._fit(\n  File \"c:\\Users\\korem\\AppData\\Local\\Programs\\Python\\Python312\\Lib\\site-packages\\scikeras\\wrappers.py\", line 936, in _fit\n    self._check_model_compatibility(y)\n  File \"c:\\Users\\korem\\AppData\\Local\\Programs\\Python\\Python312\\Lib\\site-packages\\scikeras\\wrappers.py\", line 559, in _check_model_compatibility\n    if self.n_outputs_expected_ != len(self.model_.outputs):\n                                       ^^^^^^^^^^^^^^^^^^^\n  File \"c:\\Users\\korem\\AppData\\Local\\Programs\\Python\\Python312\\Lib\\site-packages\\keras\\src\\models\\sequential.py\", line 280, in outputs\n    raise ValueError(\nValueError: Sequential model 'sequential_12' has no defined outputs yet.\n",
     "output_type": "error",
     "traceback": [
      "\u001b[1;31m---------------------------------------------------------------------------\u001b[0m",
      "\u001b[1;31mValueError\u001b[0m                                Traceback (most recent call last)",
      "Cell \u001b[1;32mIn[18], line 6\u001b[0m\n\u001b[0;32m      2\u001b[0m param_grid \u001b[38;5;241m=\u001b[39m {\u001b[38;5;124m'\u001b[39m\u001b[38;5;124mbatch_size\u001b[39m\u001b[38;5;124m'\u001b[39m: [\u001b[38;5;241m32\u001b[39m, \u001b[38;5;241m64\u001b[39m],\n\u001b[0;32m      3\u001b[0m               \u001b[38;5;124m'\u001b[39m\u001b[38;5;124mepochs\u001b[39m\u001b[38;5;124m'\u001b[39m: [\u001b[38;5;241m5\u001b[39m, \u001b[38;5;241m10\u001b[39m],\n\u001b[0;32m      4\u001b[0m               \u001b[38;5;124m'\u001b[39m\u001b[38;5;124moptimizer\u001b[39m\u001b[38;5;124m'\u001b[39m: [\u001b[38;5;124m'\u001b[39m\u001b[38;5;124madam\u001b[39m\u001b[38;5;124m'\u001b[39m, \u001b[38;5;124m'\u001b[39m\u001b[38;5;124mrmsprop\u001b[39m\u001b[38;5;124m'\u001b[39m]}\n\u001b[0;32m      5\u001b[0m grid \u001b[38;5;241m=\u001b[39m GridSearchCV(estimator\u001b[38;5;241m=\u001b[39mmodel, param_grid\u001b[38;5;241m=\u001b[39mparam_grid, n_jobs\u001b[38;5;241m=\u001b[39m\u001b[38;5;241m-\u001b[39m\u001b[38;5;241m1\u001b[39m)\n\u001b[1;32m----> 6\u001b[0m grid_result \u001b[38;5;241m=\u001b[39m \u001b[43mgrid\u001b[49m\u001b[38;5;241;43m.\u001b[39;49m\u001b[43mfit\u001b[49m\u001b[43m(\u001b[49m\u001b[43mX_train\u001b[49m\u001b[43m,\u001b[49m\u001b[43m \u001b[49m\u001b[43my_train\u001b[49m\u001b[43m)\u001b[49m\n",
      "File \u001b[1;32mc:\\Users\\korem\\AppData\\Local\\Programs\\Python\\Python312\\Lib\\site-packages\\sklearn\\base.py:1474\u001b[0m, in \u001b[0;36m_fit_context.<locals>.decorator.<locals>.wrapper\u001b[1;34m(estimator, *args, **kwargs)\u001b[0m\n\u001b[0;32m   1467\u001b[0m     estimator\u001b[38;5;241m.\u001b[39m_validate_params()\n\u001b[0;32m   1469\u001b[0m \u001b[38;5;28;01mwith\u001b[39;00m config_context(\n\u001b[0;32m   1470\u001b[0m     skip_parameter_validation\u001b[38;5;241m=\u001b[39m(\n\u001b[0;32m   1471\u001b[0m         prefer_skip_nested_validation \u001b[38;5;129;01mor\u001b[39;00m global_skip_validation\n\u001b[0;32m   1472\u001b[0m     )\n\u001b[0;32m   1473\u001b[0m ):\n\u001b[1;32m-> 1474\u001b[0m     \u001b[38;5;28;01mreturn\u001b[39;00m \u001b[43mfit_method\u001b[49m\u001b[43m(\u001b[49m\u001b[43mestimator\u001b[49m\u001b[43m,\u001b[49m\u001b[43m \u001b[49m\u001b[38;5;241;43m*\u001b[39;49m\u001b[43margs\u001b[49m\u001b[43m,\u001b[49m\u001b[43m \u001b[49m\u001b[38;5;241;43m*\u001b[39;49m\u001b[38;5;241;43m*\u001b[39;49m\u001b[43mkwargs\u001b[49m\u001b[43m)\u001b[49m\n",
      "File \u001b[1;32mc:\\Users\\korem\\AppData\\Local\\Programs\\Python\\Python312\\Lib\\site-packages\\sklearn\\model_selection\\_search.py:970\u001b[0m, in \u001b[0;36mBaseSearchCV.fit\u001b[1;34m(self, X, y, **params)\u001b[0m\n\u001b[0;32m    964\u001b[0m     results \u001b[38;5;241m=\u001b[39m \u001b[38;5;28mself\u001b[39m\u001b[38;5;241m.\u001b[39m_format_results(\n\u001b[0;32m    965\u001b[0m         all_candidate_params, n_splits, all_out, all_more_results\n\u001b[0;32m    966\u001b[0m     )\n\u001b[0;32m    968\u001b[0m     \u001b[38;5;28;01mreturn\u001b[39;00m results\n\u001b[1;32m--> 970\u001b[0m \u001b[38;5;28;43mself\u001b[39;49m\u001b[38;5;241;43m.\u001b[39;49m\u001b[43m_run_search\u001b[49m\u001b[43m(\u001b[49m\u001b[43mevaluate_candidates\u001b[49m\u001b[43m)\u001b[49m\n\u001b[0;32m    972\u001b[0m \u001b[38;5;66;03m# multimetric is determined here because in the case of a callable\u001b[39;00m\n\u001b[0;32m    973\u001b[0m \u001b[38;5;66;03m# self.scoring the return type is only known after calling\u001b[39;00m\n\u001b[0;32m    974\u001b[0m first_test_score \u001b[38;5;241m=\u001b[39m all_out[\u001b[38;5;241m0\u001b[39m][\u001b[38;5;124m\"\u001b[39m\u001b[38;5;124mtest_scores\u001b[39m\u001b[38;5;124m\"\u001b[39m]\n",
      "File \u001b[1;32mc:\\Users\\korem\\AppData\\Local\\Programs\\Python\\Python312\\Lib\\site-packages\\sklearn\\model_selection\\_search.py:1527\u001b[0m, in \u001b[0;36mGridSearchCV._run_search\u001b[1;34m(self, evaluate_candidates)\u001b[0m\n\u001b[0;32m   1525\u001b[0m \u001b[38;5;28;01mdef\u001b[39;00m \u001b[38;5;21m_run_search\u001b[39m(\u001b[38;5;28mself\u001b[39m, evaluate_candidates):\n\u001b[0;32m   1526\u001b[0m \u001b[38;5;250m    \u001b[39m\u001b[38;5;124;03m\"\"\"Search all candidates in param_grid\"\"\"\u001b[39;00m\n\u001b[1;32m-> 1527\u001b[0m     \u001b[43mevaluate_candidates\u001b[49m\u001b[43m(\u001b[49m\u001b[43mParameterGrid\u001b[49m\u001b[43m(\u001b[49m\u001b[38;5;28;43mself\u001b[39;49m\u001b[38;5;241;43m.\u001b[39;49m\u001b[43mparam_grid\u001b[49m\u001b[43m)\u001b[49m\u001b[43m)\u001b[49m\n",
      "File \u001b[1;32mc:\\Users\\korem\\AppData\\Local\\Programs\\Python\\Python312\\Lib\\site-packages\\sklearn\\model_selection\\_search.py:947\u001b[0m, in \u001b[0;36mBaseSearchCV.fit.<locals>.evaluate_candidates\u001b[1;34m(candidate_params, cv, more_results)\u001b[0m\n\u001b[0;32m    940\u001b[0m \u001b[38;5;28;01melif\u001b[39;00m \u001b[38;5;28mlen\u001b[39m(out) \u001b[38;5;241m!=\u001b[39m n_candidates \u001b[38;5;241m*\u001b[39m n_splits:\n\u001b[0;32m    941\u001b[0m     \u001b[38;5;28;01mraise\u001b[39;00m \u001b[38;5;167;01mValueError\u001b[39;00m(\n\u001b[0;32m    942\u001b[0m         \u001b[38;5;124m\"\u001b[39m\u001b[38;5;124mcv.split and cv.get_n_splits returned \u001b[39m\u001b[38;5;124m\"\u001b[39m\n\u001b[0;32m    943\u001b[0m         \u001b[38;5;124m\"\u001b[39m\u001b[38;5;124minconsistent results. Expected \u001b[39m\u001b[38;5;132;01m{}\u001b[39;00m\u001b[38;5;124m \u001b[39m\u001b[38;5;124m\"\u001b[39m\n\u001b[0;32m    944\u001b[0m         \u001b[38;5;124m\"\u001b[39m\u001b[38;5;124msplits, got \u001b[39m\u001b[38;5;132;01m{}\u001b[39;00m\u001b[38;5;124m\"\u001b[39m\u001b[38;5;241m.\u001b[39mformat(n_splits, \u001b[38;5;28mlen\u001b[39m(out) \u001b[38;5;241m/\u001b[39m\u001b[38;5;241m/\u001b[39m n_candidates)\n\u001b[0;32m    945\u001b[0m     )\n\u001b[1;32m--> 947\u001b[0m \u001b[43m_warn_or_raise_about_fit_failures\u001b[49m\u001b[43m(\u001b[49m\u001b[43mout\u001b[49m\u001b[43m,\u001b[49m\u001b[43m \u001b[49m\u001b[38;5;28;43mself\u001b[39;49m\u001b[38;5;241;43m.\u001b[39;49m\u001b[43merror_score\u001b[49m\u001b[43m)\u001b[49m\n\u001b[0;32m    949\u001b[0m \u001b[38;5;66;03m# For callable self.scoring, the return type is only know after\u001b[39;00m\n\u001b[0;32m    950\u001b[0m \u001b[38;5;66;03m# calling. If the return type is a dictionary, the error scores\u001b[39;00m\n\u001b[0;32m    951\u001b[0m \u001b[38;5;66;03m# can now be inserted with the correct key. The type checking\u001b[39;00m\n\u001b[0;32m    952\u001b[0m \u001b[38;5;66;03m# of out will be done in `_insert_error_scores`.\u001b[39;00m\n\u001b[0;32m    953\u001b[0m \u001b[38;5;28;01mif\u001b[39;00m \u001b[38;5;28mcallable\u001b[39m(\u001b[38;5;28mself\u001b[39m\u001b[38;5;241m.\u001b[39mscoring):\n",
      "File \u001b[1;32mc:\\Users\\korem\\AppData\\Local\\Programs\\Python\\Python312\\Lib\\site-packages\\sklearn\\model_selection\\_validation.py:536\u001b[0m, in \u001b[0;36m_warn_or_raise_about_fit_failures\u001b[1;34m(results, error_score)\u001b[0m\n\u001b[0;32m    529\u001b[0m \u001b[38;5;28;01mif\u001b[39;00m num_failed_fits \u001b[38;5;241m==\u001b[39m num_fits:\n\u001b[0;32m    530\u001b[0m     all_fits_failed_message \u001b[38;5;241m=\u001b[39m (\n\u001b[0;32m    531\u001b[0m         \u001b[38;5;124mf\u001b[39m\u001b[38;5;124m\"\u001b[39m\u001b[38;5;130;01m\\n\u001b[39;00m\u001b[38;5;124mAll the \u001b[39m\u001b[38;5;132;01m{\u001b[39;00mnum_fits\u001b[38;5;132;01m}\u001b[39;00m\u001b[38;5;124m fits failed.\u001b[39m\u001b[38;5;130;01m\\n\u001b[39;00m\u001b[38;5;124m\"\u001b[39m\n\u001b[0;32m    532\u001b[0m         \u001b[38;5;124m\"\u001b[39m\u001b[38;5;124mIt is very likely that your model is misconfigured.\u001b[39m\u001b[38;5;130;01m\\n\u001b[39;00m\u001b[38;5;124m\"\u001b[39m\n\u001b[0;32m    533\u001b[0m         \u001b[38;5;124m\"\u001b[39m\u001b[38;5;124mYou can try to debug the error by setting error_score=\u001b[39m\u001b[38;5;124m'\u001b[39m\u001b[38;5;124mraise\u001b[39m\u001b[38;5;124m'\u001b[39m\u001b[38;5;124m.\u001b[39m\u001b[38;5;130;01m\\n\u001b[39;00m\u001b[38;5;130;01m\\n\u001b[39;00m\u001b[38;5;124m\"\u001b[39m\n\u001b[0;32m    534\u001b[0m         \u001b[38;5;124mf\u001b[39m\u001b[38;5;124m\"\u001b[39m\u001b[38;5;124mBelow are more details about the failures:\u001b[39m\u001b[38;5;130;01m\\n\u001b[39;00m\u001b[38;5;132;01m{\u001b[39;00mfit_errors_summary\u001b[38;5;132;01m}\u001b[39;00m\u001b[38;5;124m\"\u001b[39m\n\u001b[0;32m    535\u001b[0m     )\n\u001b[1;32m--> 536\u001b[0m     \u001b[38;5;28;01mraise\u001b[39;00m \u001b[38;5;167;01mValueError\u001b[39;00m(all_fits_failed_message)\n\u001b[0;32m    538\u001b[0m \u001b[38;5;28;01melse\u001b[39;00m:\n\u001b[0;32m    539\u001b[0m     some_fits_failed_message \u001b[38;5;241m=\u001b[39m (\n\u001b[0;32m    540\u001b[0m         \u001b[38;5;124mf\u001b[39m\u001b[38;5;124m\"\u001b[39m\u001b[38;5;130;01m\\n\u001b[39;00m\u001b[38;5;132;01m{\u001b[39;00mnum_failed_fits\u001b[38;5;132;01m}\u001b[39;00m\u001b[38;5;124m fits failed out of a total of \u001b[39m\u001b[38;5;132;01m{\u001b[39;00mnum_fits\u001b[38;5;132;01m}\u001b[39;00m\u001b[38;5;124m.\u001b[39m\u001b[38;5;130;01m\\n\u001b[39;00m\u001b[38;5;124m\"\u001b[39m\n\u001b[0;32m    541\u001b[0m         \u001b[38;5;124m\"\u001b[39m\u001b[38;5;124mThe score on these train-test partitions for these parameters\u001b[39m\u001b[38;5;124m\"\u001b[39m\n\u001b[1;32m   (...)\u001b[0m\n\u001b[0;32m    545\u001b[0m         \u001b[38;5;124mf\u001b[39m\u001b[38;5;124m\"\u001b[39m\u001b[38;5;124mBelow are more details about the failures:\u001b[39m\u001b[38;5;130;01m\\n\u001b[39;00m\u001b[38;5;132;01m{\u001b[39;00mfit_errors_summary\u001b[38;5;132;01m}\u001b[39;00m\u001b[38;5;124m\"\u001b[39m\n\u001b[0;32m    546\u001b[0m     )\n",
      "\u001b[1;31mValueError\u001b[0m: \nAll the 40 fits failed.\nIt is very likely that your model is misconfigured.\nYou can try to debug the error by setting error_score='raise'.\n\nBelow are more details about the failures:\n--------------------------------------------------------------------------------\n2 fits failed with the following error:\nTraceback (most recent call last):\n  File \"c:\\Users\\korem\\AppData\\Local\\Programs\\Python\\Python312\\Lib\\site-packages\\sklearn\\model_selection\\_validation.py\", line 895, in _fit_and_score\n    estimator.fit(X_train, y_train, **fit_params)\n  File \"c:\\Users\\korem\\AppData\\Local\\Programs\\Python\\Python312\\Lib\\site-packages\\scikeras\\wrappers.py\", line 1501, in fit\n    super().fit(X=X, y=y, sample_weight=sample_weight, **kwargs)\n  File \"c:\\Users\\korem\\AppData\\Local\\Programs\\Python\\Python312\\Lib\\site-packages\\scikeras\\wrappers.py\", line 770, in fit\n    self._fit(\n  File \"c:\\Users\\korem\\AppData\\Local\\Programs\\Python\\Python312\\Lib\\site-packages\\scikeras\\wrappers.py\", line 936, in _fit\n    self._check_model_compatibility(y)\n  File \"c:\\Users\\korem\\AppData\\Local\\Programs\\Python\\Python312\\Lib\\site-packages\\scikeras\\wrappers.py\", line 559, in _check_model_compatibility\n    if self.n_outputs_expected_ != len(self.model_.outputs):\n                                       ^^^^^^^^^^^^^^^^^^^\n  File \"c:\\Users\\korem\\AppData\\Local\\Programs\\Python\\Python312\\Lib\\site-packages\\keras\\src\\models\\sequential.py\", line 280, in outputs\n    raise ValueError(\nValueError: Sequential model 'sequential_4' has no defined outputs yet.\n\n--------------------------------------------------------------------------------\n5 fits failed with the following error:\nTraceback (most recent call last):\n  File \"c:\\Users\\korem\\AppData\\Local\\Programs\\Python\\Python312\\Lib\\site-packages\\sklearn\\model_selection\\_validation.py\", line 895, in _fit_and_score\n    estimator.fit(X_train, y_train, **fit_params)\n  File \"c:\\Users\\korem\\AppData\\Local\\Programs\\Python\\Python312\\Lib\\site-packages\\scikeras\\wrappers.py\", line 1501, in fit\n    super().fit(X=X, y=y, sample_weight=sample_weight, **kwargs)\n  File \"c:\\Users\\korem\\AppData\\Local\\Programs\\Python\\Python312\\Lib\\site-packages\\scikeras\\wrappers.py\", line 770, in fit\n    self._fit(\n  File \"c:\\Users\\korem\\AppData\\Local\\Programs\\Python\\Python312\\Lib\\site-packages\\scikeras\\wrappers.py\", line 936, in _fit\n    self._check_model_compatibility(y)\n  File \"c:\\Users\\korem\\AppData\\Local\\Programs\\Python\\Python312\\Lib\\site-packages\\scikeras\\wrappers.py\", line 559, in _check_model_compatibility\n    if self.n_outputs_expected_ != len(self.model_.outputs):\n                                       ^^^^^^^^^^^^^^^^^^^\n  File \"c:\\Users\\korem\\AppData\\Local\\Programs\\Python\\Python312\\Lib\\site-packages\\keras\\src\\models\\sequential.py\", line 280, in outputs\n    raise ValueError(\nValueError: Sequential model 'sequential_5' has no defined outputs yet.\n\n--------------------------------------------------------------------------------\n7 fits failed with the following error:\nTraceback (most recent call last):\n  File \"c:\\Users\\korem\\AppData\\Local\\Programs\\Python\\Python312\\Lib\\site-packages\\sklearn\\model_selection\\_validation.py\", line 895, in _fit_and_score\n    estimator.fit(X_train, y_train, **fit_params)\n  File \"c:\\Users\\korem\\AppData\\Local\\Programs\\Python\\Python312\\Lib\\site-packages\\scikeras\\wrappers.py\", line 1501, in fit\n    super().fit(X=X, y=y, sample_weight=sample_weight, **kwargs)\n  File \"c:\\Users\\korem\\AppData\\Local\\Programs\\Python\\Python312\\Lib\\site-packages\\scikeras\\wrappers.py\", line 770, in fit\n    self._fit(\n  File \"c:\\Users\\korem\\AppData\\Local\\Programs\\Python\\Python312\\Lib\\site-packages\\scikeras\\wrappers.py\", line 936, in _fit\n    self._check_model_compatibility(y)\n  File \"c:\\Users\\korem\\AppData\\Local\\Programs\\Python\\Python312\\Lib\\site-packages\\scikeras\\wrappers.py\", line 559, in _check_model_compatibility\n    if self.n_outputs_expected_ != len(self.model_.outputs):\n                                       ^^^^^^^^^^^^^^^^^^^\n  File \"c:\\Users\\korem\\AppData\\Local\\Programs\\Python\\Python312\\Lib\\site-packages\\keras\\src\\models\\sequential.py\", line 280, in outputs\n    raise ValueError(\nValueError: Sequential model 'sequential_6' has no defined outputs yet.\n\n--------------------------------------------------------------------------------\n1 fits failed with the following error:\nTraceback (most recent call last):\n  File \"c:\\Users\\korem\\AppData\\Local\\Programs\\Python\\Python312\\Lib\\site-packages\\sklearn\\model_selection\\_validation.py\", line 895, in _fit_and_score\n    estimator.fit(X_train, y_train, **fit_params)\n  File \"c:\\Users\\korem\\AppData\\Local\\Programs\\Python\\Python312\\Lib\\site-packages\\scikeras\\wrappers.py\", line 1501, in fit\n    super().fit(X=X, y=y, sample_weight=sample_weight, **kwargs)\n  File \"c:\\Users\\korem\\AppData\\Local\\Programs\\Python\\Python312\\Lib\\site-packages\\scikeras\\wrappers.py\", line 770, in fit\n    self._fit(\n  File \"c:\\Users\\korem\\AppData\\Local\\Programs\\Python\\Python312\\Lib\\site-packages\\scikeras\\wrappers.py\", line 936, in _fit\n    self._check_model_compatibility(y)\n  File \"c:\\Users\\korem\\AppData\\Local\\Programs\\Python\\Python312\\Lib\\site-packages\\scikeras\\wrappers.py\", line 559, in _check_model_compatibility\n    if self.n_outputs_expected_ != len(self.model_.outputs):\n                                       ^^^^^^^^^^^^^^^^^^^\n  File \"c:\\Users\\korem\\AppData\\Local\\Programs\\Python\\Python312\\Lib\\site-packages\\keras\\src\\models\\sequential.py\", line 280, in outputs\n    raise ValueError(\nValueError: Sequential model 'sequential_3' has no defined outputs yet.\n\n--------------------------------------------------------------------------------\n6 fits failed with the following error:\nTraceback (most recent call last):\n  File \"c:\\Users\\korem\\AppData\\Local\\Programs\\Python\\Python312\\Lib\\site-packages\\sklearn\\model_selection\\_validation.py\", line 895, in _fit_and_score\n    estimator.fit(X_train, y_train, **fit_params)\n  File \"c:\\Users\\korem\\AppData\\Local\\Programs\\Python\\Python312\\Lib\\site-packages\\scikeras\\wrappers.py\", line 1501, in fit\n    super().fit(X=X, y=y, sample_weight=sample_weight, **kwargs)\n  File \"c:\\Users\\korem\\AppData\\Local\\Programs\\Python\\Python312\\Lib\\site-packages\\scikeras\\wrappers.py\", line 770, in fit\n    self._fit(\n  File \"c:\\Users\\korem\\AppData\\Local\\Programs\\Python\\Python312\\Lib\\site-packages\\scikeras\\wrappers.py\", line 936, in _fit\n    self._check_model_compatibility(y)\n  File \"c:\\Users\\korem\\AppData\\Local\\Programs\\Python\\Python312\\Lib\\site-packages\\scikeras\\wrappers.py\", line 559, in _check_model_compatibility\n    if self.n_outputs_expected_ != len(self.model_.outputs):\n                                       ^^^^^^^^^^^^^^^^^^^\n  File \"c:\\Users\\korem\\AppData\\Local\\Programs\\Python\\Python312\\Lib\\site-packages\\keras\\src\\models\\sequential.py\", line 280, in outputs\n    raise ValueError(\nValueError: Sequential model 'sequential_7' has no defined outputs yet.\n\n--------------------------------------------------------------------------------\n6 fits failed with the following error:\nTraceback (most recent call last):\n  File \"c:\\Users\\korem\\AppData\\Local\\Programs\\Python\\Python312\\Lib\\site-packages\\sklearn\\model_selection\\_validation.py\", line 895, in _fit_and_score\n    estimator.fit(X_train, y_train, **fit_params)\n  File \"c:\\Users\\korem\\AppData\\Local\\Programs\\Python\\Python312\\Lib\\site-packages\\scikeras\\wrappers.py\", line 1501, in fit\n    super().fit(X=X, y=y, sample_weight=sample_weight, **kwargs)\n  File \"c:\\Users\\korem\\AppData\\Local\\Programs\\Python\\Python312\\Lib\\site-packages\\scikeras\\wrappers.py\", line 770, in fit\n    self._fit(\n  File \"c:\\Users\\korem\\AppData\\Local\\Programs\\Python\\Python312\\Lib\\site-packages\\scikeras\\wrappers.py\", line 936, in _fit\n    self._check_model_compatibility(y)\n  File \"c:\\Users\\korem\\AppData\\Local\\Programs\\Python\\Python312\\Lib\\site-packages\\scikeras\\wrappers.py\", line 559, in _check_model_compatibility\n    if self.n_outputs_expected_ != len(self.model_.outputs):\n                                       ^^^^^^^^^^^^^^^^^^^\n  File \"c:\\Users\\korem\\AppData\\Local\\Programs\\Python\\Python312\\Lib\\site-packages\\keras\\src\\models\\sequential.py\", line 280, in outputs\n    raise ValueError(\nValueError: Sequential model 'sequential_8' has no defined outputs yet.\n\n--------------------------------------------------------------------------------\n5 fits failed with the following error:\nTraceback (most recent call last):\n  File \"c:\\Users\\korem\\AppData\\Local\\Programs\\Python\\Python312\\Lib\\site-packages\\sklearn\\model_selection\\_validation.py\", line 895, in _fit_and_score\n    estimator.fit(X_train, y_train, **fit_params)\n  File \"c:\\Users\\korem\\AppData\\Local\\Programs\\Python\\Python312\\Lib\\site-packages\\scikeras\\wrappers.py\", line 1501, in fit\n    super().fit(X=X, y=y, sample_weight=sample_weight, **kwargs)\n  File \"c:\\Users\\korem\\AppData\\Local\\Programs\\Python\\Python312\\Lib\\site-packages\\scikeras\\wrappers.py\", line 770, in fit\n    self._fit(\n  File \"c:\\Users\\korem\\AppData\\Local\\Programs\\Python\\Python312\\Lib\\site-packages\\scikeras\\wrappers.py\", line 936, in _fit\n    self._check_model_compatibility(y)\n  File \"c:\\Users\\korem\\AppData\\Local\\Programs\\Python\\Python312\\Lib\\site-packages\\scikeras\\wrappers.py\", line 559, in _check_model_compatibility\n    if self.n_outputs_expected_ != len(self.model_.outputs):\n                                       ^^^^^^^^^^^^^^^^^^^\n  File \"c:\\Users\\korem\\AppData\\Local\\Programs\\Python\\Python312\\Lib\\site-packages\\keras\\src\\models\\sequential.py\", line 280, in outputs\n    raise ValueError(\nValueError: Sequential model 'sequential_9' has no defined outputs yet.\n\n--------------------------------------------------------------------------------\n4 fits failed with the following error:\nTraceback (most recent call last):\n  File \"c:\\Users\\korem\\AppData\\Local\\Programs\\Python\\Python312\\Lib\\site-packages\\sklearn\\model_selection\\_validation.py\", line 895, in _fit_and_score\n    estimator.fit(X_train, y_train, **fit_params)\n  File \"c:\\Users\\korem\\AppData\\Local\\Programs\\Python\\Python312\\Lib\\site-packages\\scikeras\\wrappers.py\", line 1501, in fit\n    super().fit(X=X, y=y, sample_weight=sample_weight, **kwargs)\n  File \"c:\\Users\\korem\\AppData\\Local\\Programs\\Python\\Python312\\Lib\\site-packages\\scikeras\\wrappers.py\", line 770, in fit\n    self._fit(\n  File \"c:\\Users\\korem\\AppData\\Local\\Programs\\Python\\Python312\\Lib\\site-packages\\scikeras\\wrappers.py\", line 936, in _fit\n    self._check_model_compatibility(y)\n  File \"c:\\Users\\korem\\AppData\\Local\\Programs\\Python\\Python312\\Lib\\site-packages\\scikeras\\wrappers.py\", line 559, in _check_model_compatibility\n    if self.n_outputs_expected_ != len(self.model_.outputs):\n                                       ^^^^^^^^^^^^^^^^^^^\n  File \"c:\\Users\\korem\\AppData\\Local\\Programs\\Python\\Python312\\Lib\\site-packages\\keras\\src\\models\\sequential.py\", line 280, in outputs\n    raise ValueError(\nValueError: Sequential model 'sequential_10' has no defined outputs yet.\n\n--------------------------------------------------------------------------------\n3 fits failed with the following error:\nTraceback (most recent call last):\n  File \"c:\\Users\\korem\\AppData\\Local\\Programs\\Python\\Python312\\Lib\\site-packages\\sklearn\\model_selection\\_validation.py\", line 895, in _fit_and_score\n    estimator.fit(X_train, y_train, **fit_params)\n  File \"c:\\Users\\korem\\AppData\\Local\\Programs\\Python\\Python312\\Lib\\site-packages\\scikeras\\wrappers.py\", line 1501, in fit\n    super().fit(X=X, y=y, sample_weight=sample_weight, **kwargs)\n  File \"c:\\Users\\korem\\AppData\\Local\\Programs\\Python\\Python312\\Lib\\site-packages\\scikeras\\wrappers.py\", line 770, in fit\n    self._fit(\n  File \"c:\\Users\\korem\\AppData\\Local\\Programs\\Python\\Python312\\Lib\\site-packages\\scikeras\\wrappers.py\", line 936, in _fit\n    self._check_model_compatibility(y)\n  File \"c:\\Users\\korem\\AppData\\Local\\Programs\\Python\\Python312\\Lib\\site-packages\\scikeras\\wrappers.py\", line 559, in _check_model_compatibility\n    if self.n_outputs_expected_ != len(self.model_.outputs):\n                                       ^^^^^^^^^^^^^^^^^^^\n  File \"c:\\Users\\korem\\AppData\\Local\\Programs\\Python\\Python312\\Lib\\site-packages\\keras\\src\\models\\sequential.py\", line 280, in outputs\n    raise ValueError(\nValueError: Sequential model 'sequential_11' has no defined outputs yet.\n\n--------------------------------------------------------------------------------\n1 fits failed with the following error:\nTraceback (most recent call last):\n  File \"c:\\Users\\korem\\AppData\\Local\\Programs\\Python\\Python312\\Lib\\site-packages\\sklearn\\model_selection\\_validation.py\", line 895, in _fit_and_score\n    estimator.fit(X_train, y_train, **fit_params)\n  File \"c:\\Users\\korem\\AppData\\Local\\Programs\\Python\\Python312\\Lib\\site-packages\\scikeras\\wrappers.py\", line 1501, in fit\n    super().fit(X=X, y=y, sample_weight=sample_weight, **kwargs)\n  File \"c:\\Users\\korem\\AppData\\Local\\Programs\\Python\\Python312\\Lib\\site-packages\\scikeras\\wrappers.py\", line 770, in fit\n    self._fit(\n  File \"c:\\Users\\korem\\AppData\\Local\\Programs\\Python\\Python312\\Lib\\site-packages\\scikeras\\wrappers.py\", line 936, in _fit\n    self._check_model_compatibility(y)\n  File \"c:\\Users\\korem\\AppData\\Local\\Programs\\Python\\Python312\\Lib\\site-packages\\scikeras\\wrappers.py\", line 559, in _check_model_compatibility\n    if self.n_outputs_expected_ != len(self.model_.outputs):\n                                       ^^^^^^^^^^^^^^^^^^^\n  File \"c:\\Users\\korem\\AppData\\Local\\Programs\\Python\\Python312\\Lib\\site-packages\\keras\\src\\models\\sequential.py\", line 280, in outputs\n    raise ValueError(\nValueError: Sequential model 'sequential_12' has no defined outputs yet.\n"
     ]
    }
   ],
   "source": [
    "model = KerasClassifier(build_fn=create_model, verbose=0)\n",
    "param_grid = {'batch_size': [32, 64],\n",
    "              'epochs': [5, 10],\n",
    "              'optimizer': ['adam', 'rmsprop']}\n",
    "grid = GridSearchCV(estimator=model, param_grid=param_grid, n_jobs=-1)\n",
    "grid_result = grid.fit(X_train, y_train)"
   ]
  },
  {
   "cell_type": "code",
   "execution_count": 15,
   "metadata": {},
   "outputs": [
    {
     "ename": "NameError",
     "evalue": "name 'grid_result' is not defined",
     "output_type": "error",
     "traceback": [
      "\u001b[1;31m---------------------------------------------------------------------------\u001b[0m",
      "\u001b[1;31mNameError\u001b[0m                                 Traceback (most recent call last)",
      "Cell \u001b[1;32mIn[15], line 1\u001b[0m\n\u001b[1;32m----> 1\u001b[0m best_params \u001b[38;5;241m=\u001b[39m \u001b[43mgrid_result\u001b[49m\u001b[38;5;241m.\u001b[39mbest_params_\n\u001b[0;32m      2\u001b[0m \u001b[38;5;28mprint\u001b[39m(\u001b[38;5;124m\"\u001b[39m\u001b[38;5;124mBest Parameters: \u001b[39m\u001b[38;5;124m\"\u001b[39m, best_params)\n\u001b[0;32m      4\u001b[0m \u001b[38;5;66;03m# Train final model\u001b[39;00m\n",
      "\u001b[1;31mNameError\u001b[0m: name 'grid_result' is not defined"
     ]
    }
   ],
   "source": [
    "best_params = grid_result.best_params_\n",
    "print(\"Best Parameters: \", best_params)\n",
    "\n",
    "# Train final model\n",
    "final_model = create_model(optimizer=best_params['optimizer'])\n",
    "history = final_model.fit(X_train, y_train, batch_size=best_params['batch_size'], epochs=best_params['epochs'], validation_data=(X_test, y_test), callbacks=[ReduceLROnPlateau()])\n"
   ]
  },
  {
   "cell_type": "code",
   "execution_count": 16,
   "metadata": {},
   "outputs": [
    {
     "ename": "NameError",
     "evalue": "name 'final_model' is not defined",
     "output_type": "error",
     "traceback": [
      "\u001b[1;31m---------------------------------------------------------------------------\u001b[0m",
      "\u001b[1;31mNameError\u001b[0m                                 Traceback (most recent call last)",
      "Cell \u001b[1;32mIn[16], line 1\u001b[0m\n\u001b[1;32m----> 1\u001b[0m accuracy \u001b[38;5;241m=\u001b[39m \u001b[43mfinal_model\u001b[49m\u001b[38;5;241m.\u001b[39mevaluate(X_test, y_test, verbose\u001b[38;5;241m=\u001b[39m\u001b[38;5;241m0\u001b[39m)[\u001b[38;5;241m1\u001b[39m]\n\u001b[0;32m      2\u001b[0m \u001b[38;5;28mprint\u001b[39m(\u001b[38;5;124m\"\u001b[39m\u001b[38;5;124mTest Accuracy: \u001b[39m\u001b[38;5;124m\"\u001b[39m, accuracy)\n",
      "\u001b[1;31mNameError\u001b[0m: name 'final_model' is not defined"
     ]
    }
   ],
   "source": [
    "\n",
    "accuracy = final_model.evaluate(X_test, y_test, verbose=0)[1]\n",
    "print(\"Test Accuracy: \", accuracy)"
   ]
  },
  {
   "cell_type": "code",
   "execution_count": 17,
   "metadata": {},
   "outputs": [
    {
     "ename": "NameError",
     "evalue": "name 'history' is not defined",
     "output_type": "error",
     "traceback": [
      "\u001b[1;31m---------------------------------------------------------------------------\u001b[0m",
      "\u001b[1;31mNameError\u001b[0m                                 Traceback (most recent call last)",
      "Cell \u001b[1;32mIn[17], line 3\u001b[0m\n\u001b[0;32m      1\u001b[0m \u001b[38;5;28;01mimport\u001b[39;00m \u001b[38;5;21;01mmatplotlib\u001b[39;00m\u001b[38;5;21;01m.\u001b[39;00m\u001b[38;5;21;01mpyplot\u001b[39;00m \u001b[38;5;28;01mas\u001b[39;00m \u001b[38;5;21;01mplt\u001b[39;00m\n\u001b[1;32m----> 3\u001b[0m plt\u001b[38;5;241m.\u001b[39mplot(\u001b[43mhistory\u001b[49m\u001b[38;5;241m.\u001b[39mhistory[\u001b[38;5;124m'\u001b[39m\u001b[38;5;124maccuracy\u001b[39m\u001b[38;5;124m'\u001b[39m])\n\u001b[0;32m      4\u001b[0m plt\u001b[38;5;241m.\u001b[39mplot(history\u001b[38;5;241m.\u001b[39mhistory[\u001b[38;5;124m'\u001b[39m\u001b[38;5;124mval_accuracy\u001b[39m\u001b[38;5;124m'\u001b[39m])\n\u001b[0;32m      5\u001b[0m plt\u001b[38;5;241m.\u001b[39mtitle(\u001b[38;5;124m'\u001b[39m\u001b[38;5;124mModel Accuracy\u001b[39m\u001b[38;5;124m'\u001b[39m)\n",
      "\u001b[1;31mNameError\u001b[0m: name 'history' is not defined"
     ]
    }
   ],
   "source": [
    "import matplotlib.pyplot as plt\n",
    "\n",
    "plt.plot(history.history['accuracy'])\n",
    "plt.plot(history.history['val_accuracy'])\n",
    "plt.title('Model Accuracy')\n",
    "plt.ylabel('Accuracy')\n",
    "plt.xlabel('Epoch')\n",
    "plt.legend(['Train', 'Test'], loc='upper left')\n",
    "plt.show()"
   ]
  }
 ],
 "metadata": {
  "kernelspec": {
   "display_name": "Python 3",
   "language": "python",
   "name": "python3"
  },
  "language_info": {
   "codemirror_mode": {
    "name": "ipython",
    "version": 3
   },
   "file_extension": ".py",
   "mimetype": "text/x-python",
   "name": "python",
   "nbconvert_exporter": "python",
   "pygments_lexer": "ipython3",
   "version": "undefined.undefined.undefined"
  }
 },
 "nbformat": 4,
 "nbformat_minor": 2
}
